<?xml version="1.0" ?>
<robot name="cycle2">

<material name="silver">
  <color rgba="0.700 0.700 0.700 1.000"/>
</material>

<link name="base_link">
  <inertial>
    <origin xyz="0.0005567628751563013 -0.07313908620001963 0.5323593908185844" rpy="0 0 0"/>
    <mass value="31.679421113683862"/>
    <inertia ixx="1.4559623092538434" iyy="0.7700665203602579" izz="0.7165641494790979" ixy="0.00013918410062508692" iyz="0.2587871331853111" ixz="-3.0993364194433284e-05"/>
  </inertial>
  <visual>
    <origin xyz="0 0 0" rpy="0 0 0"/>
    <geometry>
      <mesh filename="meshes/base_link.stl" scale="0.001 0.001 0.001"/>
    </geometry>
    <material name="silver"/>
    <material/>
  </visual>
  <collision>
    <origin xyz="0 0 0" rpy="0 0 0"/>
    <geometry>
      <mesh filename="meshes/base_link.stl" scale="0.001 0.001 0.001"/>
    </geometry>
  </collision>
</link>

<link name="streeing1">
  <inertial>
    <origin xyz="-0.0004487584841056444 -0.1390970775014022 -0.3938490994450553" rpy="0 0 0"/>
    <mass value="10.063601574819897"/>
    <inertia ixx="0.15057982081641752" iyy="0.17944995328850766" izz="0.08547144177395527" ixy="-4.517566197283912e-05" iyz="-0.03939192937080538" ixz="-0.0002419046157883792"/>
  </inertial>
  <visual>
    <origin xyz="-0.00058 0.259289 -0.723563" rpy="0 0 0"/>
    <geometry>
      <mesh filename="meshes/streeing1.stl" scale="0.001 0.001 0.001"/>
    </geometry>
    <material name="silver"/>
    <material/>
  </visual>
  <collision>
    <origin xyz="-0.00058 0.259289 -0.723563" rpy="0 0 0"/>
    <geometry>
      <mesh filename="meshes/streeing1.stl" scale="0.001 0.001 0.001"/>
    </geometry>
  </collision>
</link>

<link name="front_holder1">
  <inertial>
    <origin xyz="-0.09019989305976718 4.2738175526357836e-07 -2.3596509074463867e-07" rpy="0 0 0"/>
    <mass value="0.2991463907753701"/>
    <inertia ixx="1.0057301657831474e-05" iyy="0.000816317651230275" izz="0.0008163176512302611" ixy="3.3881317890172014e-19" iyz="0.0" ixz="1.0638733817514012e-18"/>
  </inertial>
  <visual>
    <origin xyz="-0.09078 0.415366 -0.283431" rpy="0 0 0"/>
    <geometry>
      <mesh filename="meshes/front_holder1.stl" scale="0.001 0.001 0.001"/>
    </geometry>
    <material name="silver"/>
    <material/>
  </visual>
  <collision>
    <origin xyz="-0.09078 0.415366 -0.283431" rpy="0 0 0"/>
    <geometry>
      <mesh filename="meshes/front_holder1.stl" scale="0.001 0.001 0.001"/>
    </geometry>
  </collision>
</link>

<link name="front_wheel1">
  <inertial>
    <origin xyz="-0.0846352266375138 -0.02876316773673071 0.00985845310731659" rpy="0 0 0"/>
    <mass value="37.17730239042874"/>
    <inertia ixx="1.7375653799570827" iyy="0.8743078590667359" izz="0.874298799426958" ixy="-2.5172926156058484e-07" iyz="3.898829978865592e-07" ixz="-1.3856980547732878e-07"/>
  </inertial>
  <visual>
    <origin xyz="-0.09078 0.386603 -0.273572" rpy="0 0 0"/>
    <geometry>
      <mesh filename="meshes/front_wheel1.stl" scale="0.001 0.001 0.001"/>
    </geometry>
    <material name="silver"/>
    <material/>
  </visual>
  <collision>
    <origin xyz="-0.09078 0.386603 -0.273572" rpy="0 0 0"/>
    <geometry>
      <mesh filename="meshes/front_wheel1.stl" scale="0.001 0.001 0.001"/>
    </geometry>
  </collision>
</link>

<link name="pend_holder1">
  <inertial>
    <origin xyz="1.0694023293668972e-07 -0.04448466020741093 -1.8409948121522746e-08" rpy="0 0 0"/>
    <mass value="0.147533560905126"/>
    <inertia ixx="9.97988424500107e-05" iyy="4.960078317600702e-06" izz="9.97988424500237e-05" ixy="-3.3881317890172014e-21" iyz="-3.469446951953614e-18" ixz="-3.1170812458958252e-19"/>
  </inertial>
  <visual>
    <origin xyz="-0.00058 -0.207323 -0.993896" rpy="0 0 0"/>
    <geometry>
      <mesh filename="meshes/pend_holder1.stl" scale="0.001 0.001 0.001"/>
    </geometry>
    <material name="silver"/>
    <material/>
  </visual>
  <collision>
    <origin xyz="-0.00058 -0.207323 -0.993896" rpy="0 0 0"/>
    <geometry>
      <mesh filename="meshes/pend_holder1.stl" scale="0.001 0.001 0.001"/>
    </geometry>
  </collision>
</link>

<link name="pendlum1">
  <inertial>
    <origin xyz="1.889176186617523e-07 0.03834953914299745 -2.0683651347219723e-08" rpy="0 0 0"/>
    <mass value="38.41660818527807"/>
    <inertia ixx="0.9234208450776507" iyy="1.8351809153076104" izz="0.9234215646461217" ixy="5.2212548065470876e-08" iyz="-1.3725382608242853e-08" ixz="-2.29449910720686e-07"/>
  </inertial>
  <visual>
    <origin xyz="-0.00058 -0.118353 -0.993896" rpy="0 0 0"/>
    <geometry>
      <mesh filename="meshes/pendlum1.stl" scale="0.001 0.001 0.001"/>
    </geometry>
    <material name="silver"/>
    <material/>
  </visual>
  <collision>
    <origin xyz="-0.00058 -0.118353 -0.993896" rpy="0 0 0"/>
    <geometry>
      <mesh filename="meshes/pendlum1.stl" scale="0.001 0.001 0.001"/>
    </geometry>
  </collision>
</link>

<link name="base_holder1">
  <inertial>
    <origin xyz="0.013437955965770507 0.1408306073208046 -0.15926068319012132" rpy="0 0 0"/>
    <mass value="1.7402662193818301"/>
    <inertia ixx="0.027643053485653157" iyy="0.012330297386528105" izz="0.01595116429183753" ixy="-0.0007251802421858085" iyz="0.0027455523703072138" ixz="0.00015954986616242145"/>
  </inertial>
  <visual>
    <origin xyz="0.06092 -0.115023 -0.485906" rpy="0 0 0"/>
    <geometry>
      <mesh filename="meshes/base_holder1.stl" scale="0.001 0.001 0.001"/>
    </geometry>
    <material name="silver"/>
    <material/>
  </visual>
  <collision>
    <origin xyz="0.06092 -0.115023 -0.485906" rpy="0 0 0"/>
    <geometry>
      <mesh filename="meshes/base_holder1.stl" scale="0.001 0.001 0.001"/>
    </geometry>
  </collision>
</link>

<link name="rare_wheel1">
  <inertial>
    <origin xyz="-0.028382674498926133 -1.077765981516432e-06 -1.251926572964912e-07" rpy="0 0 0"/>
    <mass value="49.334829889620515"/>
    <inertia ixx="2.784418118574923" iyy="1.4010615742853512" izz="1.4010499845164919" ixy="-6.041788266596126e-07" iyz="6.757640065302439e-07" ixz="-1.7205509880019454e-07"/>
  </inertial>
  <visual>
    <origin xyz="-0.02928 -0.395448 -0.29533" rpy="0 0 0"/>
    <geometry>
      <mesh filename="meshes/rare_wheel1.stl" scale="0.001 0.001 0.001"/>
    </geometry>
    <material name="silver"/>
    <material/>
  </visual>
  <collision>
    <origin xyz="-0.02928 -0.395448 -0.29533" rpy="0 0 0"/>
    <geometry>
      <mesh filename="meshes/rare_wheel1.stl" scale="0.001 0.001 0.001"/>
    </geometry>
  </collision>
</link>

<link name="camera1">
  <inertial>
    <origin xyz="1.0694023287196285e-07 -0.0061503118949753355 -1.8104474364122325e-08" rpy="0 0 0"/>
    <mass value="0.2596943318697435"/>
    <inertia ixx="2.655655948280433e-05" iyy="0.000168797853818084" izz="0.00014878948691337754" ixy="1.1993986533120893e-18" iyz="-2.0816681711721685e-17" ixz="-1.2197274440461925e-19"/>
  </inertial>
  <visual>
    <origin xyz="-0.00058 0.339566 -0.669996" rpy="0 0 0"/>
    <geometry>
      <mesh filename="meshes/camera1.stl" scale="0.001 0.001 0.001"/>
    </geometry>
    <material name="silver"/>
    <material/>
  </visual>
  <collision>
    <origin xyz="-0.00058 0.339566 -0.669996" rpy="0 0 0"/>
    <geometry>
      <mesh filename="meshes/camera1.stl" scale="0.001 0.001 0.001"/>
    </geometry>
  </collision>
</link>

<link name="sensor21">
  <inertial>
    <origin xyz="-0.00614989305976707 -0.00022805667205980096 1.8192846305165045e-05" rpy="0 0 0"/>
    <mass value="0.019115412857786347"/>
    <inertia ixx="1.0362402175041405e-06" iyy="3.4834950673177413e-07" izz="1.169885845980908e-06" ixy="0.0" iyz="-4.201095568645563e-09" ixz="1.0842021724855044e-19"/>
  </inertial>
  <visual>
    <origin xyz="0.04862 -0.046393 -0.290886" rpy="0 0 0"/>
    <geometry>
      <mesh filename="meshes/sensor21.stl" scale="0.001 0.001 0.001"/>
    </geometry>
    <material name="silver"/>
    <material/>
  </visual>
  <collision>
    <origin xyz="0.04862 -0.046393 -0.290886" rpy="0 0 0"/>
    <geometry>
      <mesh filename="meshes/sensor21.stl" scale="0.001 0.001 0.001"/>
    </geometry>
  </collision>
</link>

<link name="sensor11">
  <inertial>
    <origin xyz="0.006150106940232929 -0.0001866862380678902 -1.119017549472412e-05" rpy="0 0 0"/>
    <mass value="0.019150156242184645"/>
    <inertia ixx="1.041309885421596e-06" iyy="3.488462314018507e-07" izz="1.1753348436667791e-06" ixy="0.0" iyz="4.0169259978841895e-09" ixz="0.0"/>
  </inertial>
  <visual>
    <origin xyz="-0.04978 -0.046283 -0.285441" rpy="0 0 0"/>
    <geometry>
      <mesh filename="meshes/sensor11.stl" scale="0.001 0.001 0.001"/>
    </geometry>
    <material name="silver"/>
    <material/>
  </visual>
  <collision>
    <origin xyz="-0.04978 -0.046283 -0.285441" rpy="0 0 0"/>
    <geometry>
      <mesh filename="meshes/sensor11.stl" scale="0.001 0.001 0.001"/>
    </geometry>
  </collision>
</link>

<joint name="streeing" type="revolute">
  <origin xyz="0.00058 -0.259289 0.723563" rpy="0 0 0"/>
  <parent link="base_link"/>
  <child link="streeing1"/>
  <axis xyz="-0.0 -0.316228 -0.948683"/>
  <limit upper="1.134464" lower="-1.134464" effort="100" velocity="100"/>
</joint>
<transmission name="streeing_tran">
  <type>transmission_interface/SimpleTransmission</type>
  <joint name="streeing">
    <hardwareInterface>PositionJointInterface</hardwareInterface>
  </joint>
  <actuator name="streeing_actr">
    <hardwareInterface>PositionJointInterface</hardwareInterface>
    <mechanicalReduction>1</mechanicalReduction>
  </actuator>
</transmission>

<joint name="front_holder" type="fixed">
  <origin xyz="0.0902 -0.156077 -0.440132" rpy="0 0 0"/>
  <parent link="streeing1"/>
  <child link="front_holder1"/>
</joint>

<joint name="frnt_wheel" type="continuous">
  <origin xyz="0.0 0.028763 -0.009859" rpy="0 0 0"/>
  <parent link="front_holder1"/>
  <child link="front_wheel1"/>
  <axis xyz="1.0 -0.0 -0.0"/>
</joint>
<transmission name="frnt_wheel_tran">
  <type>transmission_interface/SimpleTransmission</type>
  <joint name="frnt_wheel">
    <hardwareInterface>PositionJointInterface</hardwareInterface>
  </joint>
  <actuator name="frnt_wheel_actr">
    <hardwareInterface>PositionJointInterface</hardwareInterface>
    <mechanicalReduction>1</mechanicalReduction>
  </actuator>
</transmission>

<joint name="pend_holder" type="fixed">
  <origin xyz="0.00058 0.207323 0.993896" rpy="0 0 0"/>
  <parent link="base_link"/>
  <child link="pend_holder1"/>
</joint>

<joint name="pendulum" type="continuous">
  <origin xyz="0.0 -0.08897 0.0" rpy="0 0 0"/>
  <parent link="pend_holder1"/>
  <child link="pendlum1"/>
  <axis xyz="-0.0 -1.0 0.0"/>
</joint>
<transmission name="pendulum_tran">
  <type>transmission_interface/SimpleTransmission</type>
  <joint name="pendulum">
    <hardwareInterface>PositionJointInterface</hardwareInterface>
  </joint>
  <actuator name="pendulum_actr">
    <hardwareInterface>PositionJointInterface</hardwareInterface>
    <mechanicalReduction>1</mechanicalReduction>
  </actuator>
</transmission>

<joint name="base_holder" type="fixed">
  <origin xyz="-0.06092 0.115023 0.485906" rpy="0 0 0"/>
  <parent link="base_link"/>
  <child link="base_holder1"/>
</joint>

<joint name="rare_wheel" type="continuous">
  <origin xyz="0.0902 0.280425 -0.190576" rpy="0 0 0"/>
  <parent link="base_holder1"/>
  <child link="rare_wheel1"/>
  <axis xyz="1.0 -0.0 0.0"/>
</joint>
<transmission name="rare_wheel_tran">
  <type>transmission_interface/SimpleTransmission</type>
  <joint name="rare_wheel">
    <hardwareInterface>PositionJointInterface</hardwareInterface>
  </joint>
  <actuator name="rare_wheel_actr">
    <hardwareInterface>PositionJointInterface</hardwareInterface>
    <mechanicalReduction>1</mechanicalReduction>
  </actuator>
</transmission>

<joint name="camera" type="fixed">
  <origin xyz="0.00058 -0.339566 0.669996" rpy="0 0 0"/>
  <parent link="base_link"/>
  <child link="camera1"/>
</joint>

<joint name="sensor1" type="fixed">
  <origin xyz="-0.04862 0.046393 0.290886" rpy="0 0 0"/>
  <parent link="base_link"/>
  <child link="sensor21"/>
</joint>

<joint name="sensor2" type="fixed">
  <origin xyz="0.04978 0.046283 0.285441" rpy="0 0 0"/>
  <parent link="base_link"/>
  <child link="sensor11"/>
</joint>

</robot>
